2016-03-18 12:57:37,858 WARNING: Uncaught Exception: KeyError('activated',)
Traceback (most recent call last):
  File "/Library/Python/2.7/site-packages/flask/app.py", line 1475, in full_dispatch_request
    rv = self.dispatch_request()
  File "/Library/Python/2.7/site-packages/flask/app.py", line 1461, in dispatch_request
    return self.view_functions[rule.endpoint](**req.view_args)
  File "/Users/majik/github/supmice/utils/api_utils.py", line 22, in decorate
    result = f(*args, **kwargs)
  File "/Users/majik/github/supmice/blueprints/app/controllers/base.py", line 122, in app_list
    app_list.append(output_app(app, user))
  File "/Users/majik/github/supmice/blueprints/app/controllers/base.py", line 229, in output_app
    Extension.find_by_ids(trunk["extension"]["activated"])
KeyError: 'activated'
 [in /Users/majik/github/supmice/application.py:189]
2016-03-18 12:59:38,465 WARNING: Uncaught Exception: KeyError('activated',)
Traceback (most recent call last):
  File "/Library/Python/2.7/site-packages/flask/app.py", line 1475, in full_dispatch_request
    rv = self.dispatch_request()
  File "/Library/Python/2.7/site-packages/flask/app.py", line 1461, in dispatch_request
    return self.view_functions[rule.endpoint](**req.view_args)
  File "/Users/majik/github/supmice/utils/api_utils.py", line 22, in decorate
    result = f(*args, **kwargs)
  File "/Users/majik/github/supmice/blueprints/app/controllers/base.py", line 122, in app_list
    app_list.append(output_app(app, user))
  File "/Users/majik/github/supmice/blueprints/app/controllers/base.py", line 229, in output_app
    Extension.find_by_ids(trunk["extension"]["activated"])
KeyError: 'activated'
 [in /Users/majik/github/supmice/application.py:189]
2016-03-18 13:10:03,504 WARNING: Uncaught Exception: KeyError('activated',)
Traceback (most recent call last):
  File "/Library/Python/2.7/site-packages/flask/app.py", line 1475, in full_dispatch_request
    rv = self.dispatch_request()
  File "/Library/Python/2.7/site-packages/flask/app.py", line 1461, in dispatch_request
    return self.view_functions[rule.endpoint](**req.view_args)
  File "/Users/majik/github/supmice/utils/api_utils.py", line 22, in decorate
    result = f(*args, **kwargs)
  File "/Users/majik/github/supmice/blueprints/app/controllers/base.py", line 122, in app_list
    app_list.append(output_app(app, user))
  File "/Users/majik/github/supmice/blueprints/app/controllers/base.py", line 229, in output_app
    Extension.find_by_ids(trunk["extension"]["activated"])
KeyError: 'activated'
 [in /Users/majik/github/supmice/application.py:189]
2016-03-18 13:50:56,031 WARNING: Uncaught Exception: UnboundLocalError("local variable 'owner' referenced before assignment",)
Traceback (most recent call last):
  File "/Library/Python/2.7/site-packages/flask/app.py", line 1475, in full_dispatch_request
    rv = self.dispatch_request()
  File "/Library/Python/2.7/site-packages/flask/app.py", line 1461, in dispatch_request
    return self.view_functions[rule.endpoint](**req.view_args)
  File "/Users/majik/github/supmice/utils/api_utils.py", line 22, in decorate
    result = f(*args, **kwargs)
  File "/Users/majik/github/supmice/blueprints/oauth/controllers/base.py", line 147, in access_token
    if owner is None:
UnboundLocalError: local variable 'owner' referenced before assignment
 [in /Users/majik/github/supmice/application.py:189]
2016-03-18 13:51:26,530 WARNING: Uncaught Exception: UnboundLocalError("local variable 'owner' referenced before assignment",)
Traceback (most recent call last):
  File "/Library/Python/2.7/site-packages/flask/app.py", line 1475, in full_dispatch_request
    rv = self.dispatch_request()
  File "/Library/Python/2.7/site-packages/flask/app.py", line 1461, in dispatch_request
    return self.view_functions[rule.endpoint](**req.view_args)
  File "/Users/majik/github/supmice/utils/api_utils.py", line 22, in decorate
    result = f(*args, **kwargs)
  File "/Users/majik/github/supmice/blueprints/oauth/controllers/base.py", line 147, in access_token
    if owner is None:
UnboundLocalError: local variable 'owner' referenced before assignment
 [in /Users/majik/github/supmice/application.py:189]
2016-03-18 13:58:11,000 WARNING: Error: 404
Traceback (most recent call last):
  File "/Library/Python/2.7/site-packages/flask/app.py", line 1475, in full_dispatch_request
    rv = self.dispatch_request()
  File "/Library/Python/2.7/site-packages/flask/app.py", line 1453, in dispatch_request
    self.raise_routing_exception(req)
  File "/Library/Python/2.7/site-packages/flask/app.py", line 1436, in raise_routing_exception
    raise request.routing_exception
NotFound: 404: Not Found
 [in /Users/majik/github/supmice/application.py:166]
2016-03-18 13:59:52,799 WARNING: Error: 404
Traceback (most recent call last):
  File "/Library/Python/2.7/site-packages/flask/app.py", line 1475, in full_dispatch_request
    rv = self.dispatch_request()
  File "/Library/Python/2.7/site-packages/flask/app.py", line 1453, in dispatch_request
    self.raise_routing_exception(req)
  File "/Library/Python/2.7/site-packages/flask/app.py", line 1436, in raise_routing_exception
    raise request.routing_exception
NotFound: 404: Not Found
 [in /Users/majik/github/supmice/application.py:166]
2016-03-18 14:00:40,023 WARNING: Error: 404
Traceback (most recent call last):
  File "/Library/Python/2.7/site-packages/flask/app.py", line 1475, in full_dispatch_request
    rv = self.dispatch_request()
  File "/Library/Python/2.7/site-packages/flask/app.py", line 1453, in dispatch_request
    self.raise_routing_exception(req)
  File "/Library/Python/2.7/site-packages/flask/app.py", line 1436, in raise_routing_exception
    raise request.routing_exception
NotFound: 404: Not Found
 [in /Users/majik/github/supmice/application.py:166]
2016-03-18 14:01:10,466 WARNING: Error: 404
Traceback (most recent call last):
  File "/Library/Python/2.7/site-packages/flask/app.py", line 1475, in full_dispatch_request
    rv = self.dispatch_request()
  File "/Library/Python/2.7/site-packages/flask/app.py", line 1453, in dispatch_request
    self.raise_routing_exception(req)
  File "/Library/Python/2.7/site-packages/flask/app.py", line 1436, in raise_routing_exception
    raise request.routing_exception
NotFound: 404: Not Found
 [in /Users/majik/github/supmice/application.py:166]
2016-03-18 14:02:44,105 WARNING: Error: 404
Traceback (most recent call last):
  File "/Library/Python/2.7/site-packages/flask/app.py", line 1475, in full_dispatch_request
    rv = self.dispatch_request()
  File "/Library/Python/2.7/site-packages/flask/app.py", line 1453, in dispatch_request
    self.raise_routing_exception(req)
  File "/Library/Python/2.7/site-packages/flask/app.py", line 1436, in raise_routing_exception
    raise request.routing_exception
NotFound: 404: Not Found
 [in /Users/majik/github/supmice/application.py:166]
2016-03-18 14:34:47,546 WARNING: Uncaught Exception: TypeError('activate_app_ext() takes exactly 2 arguments (1 given)',)
Traceback (most recent call last):
  File "/Library/Python/2.7/site-packages/flask/app.py", line 1475, in full_dispatch_request
    rv = self.dispatch_request()
  File "/Library/Python/2.7/site-packages/flask/app.py", line 1461, in dispatch_request
    return self.view_functions[rule.endpoint](**req.view_args)
  File "/Users/majik/github/supmice/utils/api_utils.py", line 22, in decorate
    result = f(*args, **kwargs)
TypeError: activate_app_ext() takes exactly 2 arguments (1 given)
 [in /Users/majik/github/supmice/application.py:189]
2016-03-18 14:35:18,139 WARNING: Uncaught Exception: TypeError('activate_app_ext() takes exactly 2 arguments (1 given)',)
Traceback (most recent call last):
  File "/Library/Python/2.7/site-packages/flask/app.py", line 1475, in full_dispatch_request
    rv = self.dispatch_request()
  File "/Library/Python/2.7/site-packages/flask/app.py", line 1461, in dispatch_request
    return self.view_functions[rule.endpoint](**req.view_args)
  File "/Users/majik/github/supmice/utils/api_utils.py", line 22, in decorate
    result = f(*args, **kwargs)
TypeError: activate_app_ext() takes exactly 2 arguments (1 given)
 [in /Users/majik/github/supmice/application.py:189]
2016-03-25 14:26:45,303 WARNING: Uncaught Exception: ConnectionError('Error 61 connecting to 127.0.0.1:6379. Connection refused.',)
Traceback (most recent call last):
  File "/Library/Python/2.7/site-packages/flask/app.py", line 1473, in full_dispatch_request
    rv = self.preprocess_request()
  File "/Library/Python/2.7/site-packages/flask/app.py", line 1666, in preprocess_request
    rv = func()
  File "/Users/majik/github/supmice/blueprints/users/main.py", line 40, in before
    open_api = open_api_endpoints
  File "/Users/majik/github/supmice/blueprints/helpers.py", line 86, in verify_access
    verify_jwt()
  File "/Users/majik/github/supmice/blueprints/helpers.py", line 20, in verify_jwt
    raise e
ConnectionError: Error 61 connecting to 127.0.0.1:6379. Connection refused.
 [in /Users/majik/github/supmice/application.py:189]
2016-03-25 14:26:48,074 WARNING: Uncaught Exception: ConnectionError('Error 61 connecting to 127.0.0.1:6379. Connection refused.',)
Traceback (most recent call last):
  File "/Library/Python/2.7/site-packages/flask/app.py", line 1473, in full_dispatch_request
    rv = self.preprocess_request()
  File "/Library/Python/2.7/site-packages/flask/app.py", line 1666, in preprocess_request
    rv = func()
  File "/Users/majik/github/supmice/blueprints/users/main.py", line 40, in before
    open_api = open_api_endpoints
  File "/Users/majik/github/supmice/blueprints/helpers.py", line 86, in verify_access
    verify_jwt()
  File "/Users/majik/github/supmice/blueprints/helpers.py", line 20, in verify_jwt
    raise e
ConnectionError: Error 61 connecting to 127.0.0.1:6379. Connection refused.
 [in /Users/majik/github/supmice/application.py:189]
2016-03-25 14:27:07,123 WARNING: Uncaught Exception: ConnectionError('Error 61 connecting to 127.0.0.1:6379. Connection refused.',)
Traceback (most recent call last):
  File "/Library/Python/2.7/site-packages/flask/app.py", line 1473, in full_dispatch_request
    rv = self.preprocess_request()
  File "/Library/Python/2.7/site-packages/flask/app.py", line 1666, in preprocess_request
    rv = func()
  File "/Users/majik/github/supmice/blueprints/users/main.py", line 40, in before
    open_api = open_api_endpoints
  File "/Users/majik/github/supmice/blueprints/helpers.py", line 86, in verify_access
    verify_jwt()
  File "/Users/majik/github/supmice/blueprints/helpers.py", line 20, in verify_jwt
    raise e
ConnectionError: Error 61 connecting to 127.0.0.1:6379. Connection refused.
 [in /Users/majik/github/supmice/application.py:189]
2016-03-25 14:27:08,259 WARNING: Uncaught Exception: ConnectionError('Error 61 connecting to 127.0.0.1:6379. Connection refused.',)
Traceback (most recent call last):
  File "/Library/Python/2.7/site-packages/flask/app.py", line 1473, in full_dispatch_request
    rv = self.preprocess_request()
  File "/Library/Python/2.7/site-packages/flask/app.py", line 1666, in preprocess_request
    rv = func()
  File "/Users/majik/github/supmice/blueprints/users/main.py", line 40, in before
    open_api = open_api_endpoints
  File "/Users/majik/github/supmice/blueprints/helpers.py", line 86, in verify_access
    verify_jwt()
  File "/Users/majik/github/supmice/blueprints/helpers.py", line 20, in verify_jwt
    raise e
ConnectionError: Error 61 connecting to 127.0.0.1:6379. Connection refused.
 [in /Users/majik/github/supmice/application.py:189]
2016-03-25 14:27:13,145 WARNING: Uncaught Exception: ConnectionError('Error 61 connecting to 127.0.0.1:6379. Connection refused.',)
Traceback (most recent call last):
  File "/Library/Python/2.7/site-packages/flask/app.py", line 1473, in full_dispatch_request
    rv = self.preprocess_request()
  File "/Library/Python/2.7/site-packages/flask/app.py", line 1666, in preprocess_request
    rv = func()
  File "/Users/majik/github/supmice/blueprints/users/main.py", line 40, in before
    open_api = open_api_endpoints
  File "/Users/majik/github/supmice/blueprints/helpers.py", line 86, in verify_access
    verify_jwt()
  File "/Users/majik/github/supmice/blueprints/helpers.py", line 20, in verify_jwt
    raise e
ConnectionError: Error 61 connecting to 127.0.0.1:6379. Connection refused.
 [in /Users/majik/github/supmice/application.py:189]
2016-03-25 14:27:18,424 WARNING: Uncaught Exception: ConnectionError('Error 61 connecting to 127.0.0.1:6379. Connection refused.',)
Traceback (most recent call last):
  File "/Library/Python/2.7/site-packages/flask/app.py", line 1473, in full_dispatch_request
    rv = self.preprocess_request()
  File "/Library/Python/2.7/site-packages/flask/app.py", line 1666, in preprocess_request
    rv = func()
  File "/Users/majik/github/supmice/blueprints/users/main.py", line 40, in before
    open_api = open_api_endpoints
  File "/Users/majik/github/supmice/blueprints/helpers.py", line 86, in verify_access
    verify_jwt()
  File "/Users/majik/github/supmice/blueprints/helpers.py", line 20, in verify_jwt
    raise e
ConnectionError: Error 61 connecting to 127.0.0.1:6379. Connection refused.
 [in /Users/majik/github/supmice/application.py:189]
2016-03-25 14:29:18,044 WARNING: Uncaught Exception: MailQueuePushFailed()
Traceback (most recent call last):
  File "/Library/Python/2.7/site-packages/flask/app.py", line 1475, in full_dispatch_request
    rv = self.dispatch_request()
  File "/Library/Python/2.7/site-packages/flask/app.py", line 1461, in dispatch_request
    return self.view_functions[rule.endpoint](**req.view_args)
  File "/Users/majik/github/supmice/utils/api_utils.py", line 22, in decorate
    result = f(*args, **kwargs)
  File "/Users/majik/github/supmice/blueprints/users/controllers/base.py", line 137, in register_user
    context)
  File "/Users/majik/github/supmice/services/mail_push/mail_push.py", line 71, in send_system_mail
    self._push_single_mail(send_mail)
  File "/Users/majik/github/supmice/services/mail_push/mail_push.py", line 39, in _push_single_mail
    raise MailQueuePushFailed
MailQueuePushFailed: MAIL_QUEUE_PUSH_FAILED:None
 [in /Users/majik/github/supmice/application.py:189]
2016-03-25 16:23:18,825 WARNING: Uncaught Exception: NameError("global name 'parse_int' is not defined",)
Traceback (most recent call last):
  File "/Library/Python/2.7/site-packages/flask/app.py", line 1475, in full_dispatch_request
    rv = self.dispatch_request()
  File "/Library/Python/2.7/site-packages/flask/app.py", line 1461, in dispatch_request
    return self.view_functions[rule.endpoint](**req.view_args)
  File "/Users/majik/github/supmice/utils/api_utils.py", line 22, in decorate
    result = f(*args, **kwargs)
  File "/Users/majik/github/supmice/blueprints/member/controllers/oauth.py", line 45, in oauth_list_members
    offset = parse_int(offset)
NameError: global name 'parse_int' is not defined
 [in /Users/majik/github/supmice/application.py:189]
2016-03-25 16:23:18,832 WARNING: Uncaught Exception: NameError("global name 'parse_int' is not defined",)
Traceback (most recent call last):
  File "/Library/Python/2.7/site-packages/flask/app.py", line 1475, in full_dispatch_request
    rv = self.dispatch_request()
  File "/Library/Python/2.7/site-packages/flask/app.py", line 1461, in dispatch_request
    return self.view_functions[rule.endpoint](**req.view_args)
  File "/Users/majik/github/supmice/utils/api_utils.py", line 22, in decorate
    result = f(*args, **kwargs)
  File "/Users/majik/github/supmice/blueprints/member/controllers/oauth.py", line 45, in oauth_list_members
    offset = parse_int(offset)
NameError: global name 'parse_int' is not defined
 [in /Users/majik/github/supmice/application.py:189]
2016-03-25 16:23:18,839 WARNING: Uncaught Exception: NameError("global name 'parse_int' is not defined",)
Traceback (most recent call last):
  File "/Library/Python/2.7/site-packages/flask/app.py", line 1475, in full_dispatch_request
    rv = self.dispatch_request()
  File "/Library/Python/2.7/site-packages/flask/app.py", line 1461, in dispatch_request
    return self.view_functions[rule.endpoint](**req.view_args)
  File "/Users/majik/github/supmice/utils/api_utils.py", line 22, in decorate
    result = f(*args, **kwargs)
  File "/Users/majik/github/supmice/blueprints/member/controllers/oauth.py", line 45, in oauth_list_members
    offset = parse_int(offset)
NameError: global name 'parse_int' is not defined
 [in /Users/majik/github/supmice/application.py:189]
2016-03-25 16:23:18,845 WARNING: Uncaught Exception: NameError("global name 'parse_int' is not defined",)
Traceback (most recent call last):
  File "/Library/Python/2.7/site-packages/flask/app.py", line 1475, in full_dispatch_request
    rv = self.dispatch_request()
  File "/Library/Python/2.7/site-packages/flask/app.py", line 1461, in dispatch_request
    return self.view_functions[rule.endpoint](**req.view_args)
  File "/Users/majik/github/supmice/utils/api_utils.py", line 22, in decorate
    result = f(*args, **kwargs)
  File "/Users/majik/github/supmice/blueprints/member/controllers/oauth.py", line 45, in oauth_list_members
    offset = parse_int(offset)
NameError: global name 'parse_int' is not defined
 [in /Users/majik/github/supmice/application.py:189]
2016-03-25 16:23:48,027 WARNING: Uncaught Exception: NameError("global name 'parse_int' is not defined",)
Traceback (most recent call last):
  File "/Library/Python/2.7/site-packages/flask/app.py", line 1475, in full_dispatch_request
    rv = self.dispatch_request()
  File "/Library/Python/2.7/site-packages/flask/app.py", line 1461, in dispatch_request
    return self.view_functions[rule.endpoint](**req.view_args)
  File "/Users/majik/github/supmice/utils/api_utils.py", line 22, in decorate
    result = f(*args, **kwargs)
  File "/Users/majik/github/supmice/blueprints/member/controllers/oauth.py", line 45, in oauth_list_members
    offset = parse_int(offset)
NameError: global name 'parse_int' is not defined
 [in /Users/majik/github/supmice/application.py:189]
2016-03-25 16:23:48,036 WARNING: Uncaught Exception: NameError("global name 'parse_int' is not defined",)
Traceback (most recent call last):
  File "/Library/Python/2.7/site-packages/flask/app.py", line 1475, in full_dispatch_request
    rv = self.dispatch_request()
  File "/Library/Python/2.7/site-packages/flask/app.py", line 1461, in dispatch_request
    return self.view_functions[rule.endpoint](**req.view_args)
  File "/Users/majik/github/supmice/utils/api_utils.py", line 22, in decorate
    result = f(*args, **kwargs)
  File "/Users/majik/github/supmice/blueprints/member/controllers/oauth.py", line 45, in oauth_list_members
    offset = parse_int(offset)
NameError: global name 'parse_int' is not defined
 [in /Users/majik/github/supmice/application.py:189]
2016-03-25 16:23:48,042 WARNING: Uncaught Exception: NameError("global name 'parse_int' is not defined",)
Traceback (most recent call last):
  File "/Library/Python/2.7/site-packages/flask/app.py", line 1475, in full_dispatch_request
    rv = self.dispatch_request()
  File "/Library/Python/2.7/site-packages/flask/app.py", line 1461, in dispatch_request
    return self.view_functions[rule.endpoint](**req.view_args)
  File "/Users/majik/github/supmice/utils/api_utils.py", line 22, in decorate
    result = f(*args, **kwargs)
  File "/Users/majik/github/supmice/blueprints/member/controllers/oauth.py", line 45, in oauth_list_members
    offset = parse_int(offset)
NameError: global name 'parse_int' is not defined
 [in /Users/majik/github/supmice/application.py:189]
2016-03-25 16:23:48,048 WARNING: Uncaught Exception: NameError("global name 'parse_int' is not defined",)
Traceback (most recent call last):
  File "/Library/Python/2.7/site-packages/flask/app.py", line 1475, in full_dispatch_request
    rv = self.dispatch_request()
  File "/Library/Python/2.7/site-packages/flask/app.py", line 1461, in dispatch_request
    return self.view_functions[rule.endpoint](**req.view_args)
  File "/Users/majik/github/supmice/utils/api_utils.py", line 22, in decorate
    result = f(*args, **kwargs)
  File "/Users/majik/github/supmice/blueprints/member/controllers/oauth.py", line 45, in oauth_list_members
    offset = parse_int(offset)
NameError: global name 'parse_int' is not defined
 [in /Users/majik/github/supmice/application.py:189]
2016-03-25 16:46:39,454 WARNING: Uncaught Exception: NameError("global name 'output_role' is not defined",)
Traceback (most recent call last):
  File "/Library/Python/2.7/site-packages/flask/app.py", line 1475, in full_dispatch_request
    rv = self.dispatch_request()
  File "/Library/Python/2.7/site-packages/flask/app.py", line 1461, in dispatch_request
    return self.view_functions[rule.endpoint](**req.view_args)
  File "/Users/majik/github/supmice/utils/api_utils.py", line 22, in decorate
    result = f(*args, **kwargs)
  File "/Users/majik/github/supmice/blueprints/member/controllers/oauth.py", line 33, in oauth_list_roles
    role_list = [output_role(role) for role in roles]
NameError: global name 'output_role' is not defined
 [in /Users/majik/github/supmice/application.py:189]
2016-04-07 15:19:12,115 WARNING: Uncaught Exception: ConnectionError('Error 61 connecting to 127.0.0.1:6379. Connection refused.',)
Traceback (most recent call last):
  File "/Library/Python/2.7/site-packages/flask/app.py", line 1473, in full_dispatch_request
    rv = self.preprocess_request()
  File "/Library/Python/2.7/site-packages/flask/app.py", line 1666, in preprocess_request
    rv = func()
  File "/Users/majik/github/supmice/blueprints/users/main.py", line 40, in before
    open_api = open_api_endpoints
  File "/Users/majik/github/supmice/blueprints/helpers.py", line 76, in verify_access
    verify_jwt()
  File "/Users/majik/github/supmice/blueprints/helpers.py", line 19, in verify_jwt
    raise e
ConnectionError: Error 61 connecting to 127.0.0.1:6379. Connection refused.
 [in /Users/majik/github/supmice/application.py:183]
2016-04-07 15:19:15,852 WARNING: Uncaught Exception: ConnectionError('Error 61 connecting to 127.0.0.1:6379. Connection refused.',)
Traceback (most recent call last):
  File "/Library/Python/2.7/site-packages/flask/app.py", line 1473, in full_dispatch_request
    rv = self.preprocess_request()
  File "/Library/Python/2.7/site-packages/flask/app.py", line 1666, in preprocess_request
    rv = func()
  File "/Users/majik/github/supmice/blueprints/users/main.py", line 40, in before
    open_api = open_api_endpoints
  File "/Users/majik/github/supmice/blueprints/helpers.py", line 76, in verify_access
    verify_jwt()
  File "/Users/majik/github/supmice/blueprints/helpers.py", line 19, in verify_jwt
    raise e
ConnectionError: Error 61 connecting to 127.0.0.1:6379. Connection refused.
 [in /Users/majik/github/supmice/application.py:183]
2016-04-07 15:19:18,633 WARNING: Uncaught Exception: ConnectionError('Error 61 connecting to 127.0.0.1:6379. Connection refused.',)
Traceback (most recent call last):
  File "/Library/Python/2.7/site-packages/flask/app.py", line 1473, in full_dispatch_request
    rv = self.preprocess_request()
  File "/Library/Python/2.7/site-packages/flask/app.py", line 1666, in preprocess_request
    rv = func()
  File "/Users/majik/github/supmice/blueprints/users/main.py", line 40, in before
    open_api = open_api_endpoints
  File "/Users/majik/github/supmice/blueprints/helpers.py", line 76, in verify_access
    verify_jwt()
  File "/Users/majik/github/supmice/blueprints/helpers.py", line 19, in verify_jwt
    raise e
ConnectionError: Error 61 connecting to 127.0.0.1:6379. Connection refused.
 [in /Users/majik/github/supmice/application.py:183]
2016-04-07 15:20:46,035 WARNING: Uncaught Exception: ConnectionError('Error 61 connecting to 127.0.0.1:6379. Connection refused.',)
Traceback (most recent call last):
  File "/Library/Python/2.7/site-packages/flask/app.py", line 1475, in full_dispatch_request
    rv = self.dispatch_request()
  File "/Library/Python/2.7/site-packages/flask/app.py", line 1461, in dispatch_request
    return self.view_functions[rule.endpoint](**req.view_args)
  File "/Users/majik/github/supmice/utils/api_utils.py", line 22, in decorate
    result = f(*args, **kwargs)
  File "/Users/majik/github/supmice/blueprints/users/controllers/base.py", line 85, in register_user
    if current_app.redis.get("inactivated-{}".format(login)):
  File "/Library/Python/2.7/site-packages/redis/client.py", line 807, in get
    return self.execute_command('GET', name)
  File "/Library/Python/2.7/site-packages/redis/client.py", line 534, in execute_command
    connection.send_command(*args)
  File "/Library/Python/2.7/site-packages/redis/connection.py", line 532, in send_command
    self.send_packed_command(self.pack_command(*args))
  File "/Library/Python/2.7/site-packages/redis/connection.py", line 508, in send_packed_command
    self.connect()
  File "/Library/Python/2.7/site-packages/redis/connection.py", line 412, in connect
    raise ConnectionError(self._error_message(e))
ConnectionError: Error 61 connecting to 127.0.0.1:6379. Connection refused.
 [in /Users/majik/github/supmice/application.py:183]
2016-04-07 15:47:13,485 WARNING: Uncaught Exception: TypeError("'NoneType' object has no attribute '__getitem__'",)
Traceback (most recent call last):
  File "/Library/Python/2.7/site-packages/flask/app.py", line 1475, in full_dispatch_request
    rv = self.dispatch_request()
  File "/Library/Python/2.7/site-packages/flask/app.py", line 1461, in dispatch_request
    return self.view_functions[rule.endpoint](**req.view_args)
  File "/Users/majik/github/supmice/utils/api_utils.py", line 22, in decorate
    result = f(*args, **kwargs)
  File "/Users/majik/github/supmice/blueprints/oauth/controllers/base.py", line 152, in access_token
    user_id = str(app["owner_id"])
TypeError: 'NoneType' object has no attribute '__getitem__'
 [in /Users/majik/github/supmice/application.py:183]
2016-04-07 16:03:00,204 WARNING: Uncaught Exception: TypeError("'NoneType' object has no attribute '__getitem__'",)
Traceback (most recent call last):
  File "/Library/Python/2.7/site-packages/flask/app.py", line 1475, in full_dispatch_request
    rv = self.dispatch_request()
  File "/Library/Python/2.7/site-packages/flask/app.py", line 1461, in dispatch_request
    return self.view_functions[rule.endpoint](**req.view_args)
  File "/Users/majik/github/supmice/utils/api_utils.py", line 22, in decorate
    result = f(*args, **kwargs)
  File "/Users/majik/github/supmice/blueprints/oauth/controllers/base.py", line 149, in access_token
    user_id = str(app["owner_id"])
TypeError: 'NoneType' object has no attribute '__getitem__'
 [in /Users/majik/github/supmice/application.py:183]
2016-04-13 16:21:02,497 WARNING: Uncaught Exception: ConnectionError('Error 61 connecting to 127.0.0.1:6379. Connection refused.',)
Traceback (most recent call last):
  File "/Library/Python/2.7/site-packages/flask/app.py", line 1475, in full_dispatch_request
    rv = self.dispatch_request()
  File "/Library/Python/2.7/site-packages/flask/app.py", line 1461, in dispatch_request
    return self.view_functions[rule.endpoint](**req.view_args)
  File "/Users/majik/github/supmice/utils/api_utils.py", line 22, in decorate
    result = f(*args, **kwargs)
  File "/Users/majik/github/supmice/blueprints/users/controllers/base.py", line 85, in register_user
    if current_app.redis.get("inactivated-{}".format(login)):
  File "/Library/Python/2.7/site-packages/redis/client.py", line 807, in get
    return self.execute_command('GET', name)
  File "/Library/Python/2.7/site-packages/redis/client.py", line 534, in execute_command
    connection.send_command(*args)
  File "/Library/Python/2.7/site-packages/redis/connection.py", line 532, in send_command
    self.send_packed_command(self.pack_command(*args))
  File "/Library/Python/2.7/site-packages/redis/connection.py", line 508, in send_packed_command
    self.connect()
  File "/Library/Python/2.7/site-packages/redis/connection.py", line 412, in connect
    raise ConnectionError(self._error_message(e))
ConnectionError: Error 61 connecting to 127.0.0.1:6379. Connection refused.
 [in /Users/majik/github/supmice/application.py:183]
2016-05-03 16:45:33,819 WARNING: Error: 404
Traceback (most recent call last):
  File "/Library/Python/2.7/site-packages/flask/app.py", line 1475, in full_dispatch_request
    rv = self.dispatch_request()
  File "/Library/Python/2.7/site-packages/flask/app.py", line 1453, in dispatch_request
    self.raise_routing_exception(req)
  File "/Library/Python/2.7/site-packages/flask/app.py", line 1436, in raise_routing_exception
    raise request.routing_exception
NotFound: 404: Not Found
 [in /Users/majik/github/throwcat/server/application.py:141]
2016-05-03 16:47:37,222 WARNING: Uncaught Exception: TypeError("verify_access() got an unexpected keyword argument 'open_apis'",)
Traceback (most recent call last):
  File "/Library/Python/2.7/site-packages/flask/app.py", line 1473, in full_dispatch_request
    rv = self.preprocess_request()
  File "/Library/Python/2.7/site-packages/flask/app.py", line 1666, in preprocess_request
    rv = func()
  File "/Users/majik/github/throwcat/server/blueprints/user/main.py", line 36, in before
    user_apis=user_api_endpoints)
TypeError: verify_access() got an unexpected keyword argument 'open_apis'
 [in /Users/majik/github/throwcat/server/application.py:164]
2016-05-03 16:48:46,016 WARNING: Uncaught Exception: TypeError("verify_access() got an unexpected keyword argument 'user_apis'",)
Traceback (most recent call last):
  File "/Library/Python/2.7/site-packages/flask/app.py", line 1473, in full_dispatch_request
    rv = self.preprocess_request()
  File "/Library/Python/2.7/site-packages/flask/app.py", line 1666, in preprocess_request
    rv = func()
  File "/Users/majik/github/throwcat/server/blueprints/user/main.py", line 36, in before
    user_apis=user_api_endpoints)
TypeError: verify_access() got an unexpected keyword argument 'user_apis'
 [in /Users/majik/github/throwcat/server/application.py:164]
2016-05-03 16:49:33,181 WARNING: Uncaught Exception: TypeError("verify_access() got an unexpected keyword argument 'user_apis'",)
Traceback (most recent call last):
  File "/Library/Python/2.7/site-packages/flask/app.py", line 1473, in full_dispatch_request
    rv = self.preprocess_request()
  File "/Library/Python/2.7/site-packages/flask/app.py", line 1666, in preprocess_request
    rv = func()
  File "/Users/majik/github/throwcat/server/blueprints/user/main.py", line 36, in before
    user_apis=user_api_endpoints)
TypeError: verify_access() got an unexpected keyword argument 'user_apis'
 [in /Users/majik/github/throwcat/server/application.py:164]
2016-05-03 16:49:45,254 WARNING: Uncaught Exception: TypeError("verify_access() got an unexpected keyword argument 'user_apis'",)
Traceback (most recent call last):
  File "/Library/Python/2.7/site-packages/flask/app.py", line 1473, in full_dispatch_request
    rv = self.preprocess_request()
  File "/Library/Python/2.7/site-packages/flask/app.py", line 1666, in preprocess_request
    rv = func()
  File "/Users/majik/github/throwcat/server/blueprints/user/main.py", line 36, in before
    user_apis=user_api_endpoints)
TypeError: verify_access() got an unexpected keyword argument 'user_apis'
 [in /Users/majik/github/throwcat/server/application.py:164]
2016-05-03 16:53:46,249 WARNING: Uncaught Exception: ConnectionError('Error 61 connecting to 127.0.0.1:6379. Connection refused.',)
Traceback (most recent call last):
  File "/Library/Python/2.7/site-packages/flask/app.py", line 1475, in full_dispatch_request
    rv = self.dispatch_request()
  File "/Library/Python/2.7/site-packages/flask/app.py", line 1461, in dispatch_request
    return self.view_functions[rule.endpoint](**req.view_args)
  File "/Users/majik/github/throwcat/server/utils/api_utils.py", line 22, in decorate
    result = f(*args, **kwargs)
  File "/Users/majik/github/throwcat/server/blueprints/user/controllers.py", line 22, in get_captcha
    captcha = send_captcha_by_email(email)
  File "/Users/majik/github/throwcat/server/blueprints/user/controllers.py", line 214, in send_captcha_by_email
    captcha = set_captcha(email)
  File "/Users/majik/github/throwcat/server/blueprints/user/controllers.py", line 163, in set_captcha
    current_app.redis.setex(key, num, EXPIRE)
  File "/Library/Python/2.7/site-packages/redis/client.py", line 1925, in setex
    return self.execute_command('SETEX', name, time, value)
  File "/Library/Python/2.7/site-packages/redis/client.py", line 534, in execute_command
    connection.send_command(*args)
  File "/Library/Python/2.7/site-packages/redis/connection.py", line 532, in send_command
    self.send_packed_command(self.pack_command(*args))
  File "/Library/Python/2.7/site-packages/redis/connection.py", line 508, in send_packed_command
    self.connect()
  File "/Library/Python/2.7/site-packages/redis/connection.py", line 412, in connect
    raise ConnectionError(self._error_message(e))
ConnectionError: Error 61 connecting to 127.0.0.1:6379. Connection refused.
 [in /Users/majik/github/throwcat/server/application.py:164]
2016-05-03 16:56:45,362 WARNING: Uncaught Exception: Exception('Captcha Error',)
Traceback (most recent call last):
  File "/Library/Python/2.7/site-packages/flask/app.py", line 1475, in full_dispatch_request
    rv = self.dispatch_request()
  File "/Library/Python/2.7/site-packages/flask/app.py", line 1461, in dispatch_request
    return self.view_functions[rule.endpoint](**req.view_args)
  File "/Users/majik/github/throwcat/server/utils/api_utils.py", line 22, in decorate
    result = f(*args, **kwargs)
  File "/Users/majik/github/throwcat/server/blueprints/user/controllers.py", line 46, in regsister
    raise Exception("Captcha Error")
Exception: Captcha Error
 [in /Users/majik/github/throwcat/server/application.py:164]
2016-05-03 16:57:39,218 WARNING: Uncaught Exception: Exception('Captcha Error',)
Traceback (most recent call last):
  File "/Library/Python/2.7/site-packages/flask/app.py", line 1475, in full_dispatch_request
    rv = self.dispatch_request()
  File "/Library/Python/2.7/site-packages/flask/app.py", line 1461, in dispatch_request
    return self.view_functions[rule.endpoint](**req.view_args)
  File "/Users/majik/github/throwcat/server/utils/api_utils.py", line 22, in decorate
    result = f(*args, **kwargs)
  File "/Users/majik/github/throwcat/server/blueprints/user/controllers.py", line 46, in regsister
    raise Exception("Captcha Error")
Exception: Captcha Error
 [in /Users/majik/github/throwcat/server/application.py:164]
2016-05-03 16:59:48,825 WARNING: Uncaught Exception: Exception('Captcha Error',)
Traceback (most recent call last):
  File "/Library/Python/2.7/site-packages/flask/app.py", line 1475, in full_dispatch_request
    rv = self.dispatch_request()
  File "/Library/Python/2.7/site-packages/flask/app.py", line 1461, in dispatch_request
    return self.view_functions[rule.endpoint](**req.view_args)
  File "/Users/majik/github/throwcat/server/utils/api_utils.py", line 22, in decorate
    result = f(*args, **kwargs)
  File "/Users/majik/github/throwcat/server/blueprints/user/controllers.py", line 46, in regsister
    raise Exception("Captcha Error")
Exception: Captcha Error
 [in /Users/majik/github/throwcat/server/application.py:164]
2016-05-03 17:01:08,829 WARNING: Uncaught Exception: Exception('Captcha Error',)
Traceback (most recent call last):
  File "/Library/Python/2.7/site-packages/flask/app.py", line 1475, in full_dispatch_request
    rv = self.dispatch_request()
  File "/Library/Python/2.7/site-packages/flask/app.py", line 1461, in dispatch_request
    return self.view_functions[rule.endpoint](**req.view_args)
  File "/Users/majik/github/throwcat/server/utils/api_utils.py", line 22, in decorate
    result = f(*args, **kwargs)
  File "/Users/majik/github/throwcat/server/blueprints/user/controllers.py", line 46, in regsister
    raise Exception("Captcha Error")
Exception: Captcha Error
 [in /Users/majik/github/throwcat/server/application.py:164]
2016-05-03 17:01:37,322 WARNING: Uncaught Exception: Exception('Captcha Error',)
Traceback (most recent call last):
  File "/Library/Python/2.7/site-packages/flask/app.py", line 1475, in full_dispatch_request
    rv = self.dispatch_request()
  File "/Library/Python/2.7/site-packages/flask/app.py", line 1461, in dispatch_request
    return self.view_functions[rule.endpoint](**req.view_args)
  File "/Users/majik/github/throwcat/server/utils/api_utils.py", line 22, in decorate
    result = f(*args, **kwargs)
  File "/Users/majik/github/throwcat/server/blueprints/user/controllers.py", line 46, in regsister
    raise Exception("Captcha Error")
Exception: Captcha Error
 [in /Users/majik/github/throwcat/server/application.py:164]
2016-05-03 17:02:31,455 WARNING: Uncaught Exception: Exception('Captcha Error',)
Traceback (most recent call last):
  File "/Library/Python/2.7/site-packages/flask/app.py", line 1475, in full_dispatch_request
    rv = self.dispatch_request()
  File "/Library/Python/2.7/site-packages/flask/app.py", line 1461, in dispatch_request
    return self.view_functions[rule.endpoint](**req.view_args)
  File "/Users/majik/github/throwcat/server/utils/api_utils.py", line 22, in decorate
    result = f(*args, **kwargs)
  File "/Users/majik/github/throwcat/server/blueprints/user/controllers.py", line 46, in regsister
    raise Exception("Captcha Error")
Exception: Captcha Error
 [in /Users/majik/github/throwcat/server/application.py:164]
2016-05-03 17:07:56,534 WARNING: Uncaught Exception: Exception('Login exists',)
Traceback (most recent call last):
  File "/Library/Python/2.7/site-packages/flask/app.py", line 1475, in full_dispatch_request
    rv = self.dispatch_request()
  File "/Library/Python/2.7/site-packages/flask/app.py", line 1461, in dispatch_request
    return self.view_functions[rule.endpoint](**req.view_args)
  File "/Users/majik/github/throwcat/server/utils/api_utils.py", line 22, in decorate
    result = f(*args, **kwargs)
  File "/Users/majik/github/throwcat/server/blueprints/user/controllers.py", line 43, in regsister
    raise Exception("Login exists")
Exception: Login exists
 [in /Users/majik/github/throwcat/server/application.py:164]
2016-05-03 17:09:09,218 WARNING: Uncaught Exception: InvalidDocument('Cannot encode object: <function login at 0x10b512230>',)
Traceback (most recent call last):
  File "/Library/Python/2.7/site-packages/flask/app.py", line 1475, in full_dispatch_request
    rv = self.dispatch_request()
  File "/Library/Python/2.7/site-packages/flask/app.py", line 1461, in dispatch_request
    return self.view_functions[rule.endpoint](**req.view_args)
  File "/Users/majik/github/throwcat/server/utils/api_utils.py", line 22, in decorate
    result = f(*args, **kwargs)
  File "/Users/majik/github/throwcat/server/blueprints/user/controllers.py", line 72, in get_recovery_captcha
    if not User.find_one_by_login(login):
  File "/Users/majik/github/throwcat/server/common_models/user.py", line 50, in find_one_by_login
    "deleted": False
  File "/Library/Python/2.7/site-packages/mongokit/document.py", line 300, in find_one
    return self.collection.find_one(wrap=self._obj_class, *args, **kwargs)
  File "/Library/Python/2.7/site-packages/pymongo/collection.py", line 721, in find_one
    for result in cursor.limit(-1):
  File "/Library/Python/2.7/site-packages/mongokit/cursor.py", line 42, in next
    if len(self.__data) or self._refresh():
  File "/Library/Python/2.7/site-packages/pymongo/cursor.py", line 982, in _refresh
    self.__uuid_subtype))
InvalidDocument: Cannot encode object: <function login at 0x10b512230>
 [in /Users/majik/github/throwcat/server/application.py:164]
2016-05-03 17:16:08,384 WARNING: Uncaught Exception: TypeError("int() argument must be a string or a number, not 'NoneType'",)
Traceback (most recent call last):
  File "/Library/Python/2.7/site-packages/flask/app.py", line 1475, in full_dispatch_request
    rv = self.dispatch_request()
  File "/Library/Python/2.7/site-packages/flask/app.py", line 1461, in dispatch_request
    return self.view_functions[rule.endpoint](**req.view_args)
  File "/Users/majik/github/throwcat/server/utils/api_utils.py", line 22, in decorate
    result = f(*args, **kwargs)
  File "/Users/majik/github/throwcat/server/blueprints/user/controllers.py", line 101, in recovery
    if not check_recovery_captcha(login, captcha):
  File "/Users/majik/github/throwcat/server/blueprints/user/controllers.py", line 208, in check_recovery_captcha
    num = int(current_app.redis.get(key))
TypeError: int() argument must be a string or a number, not 'NoneType'
 [in /Users/majik/github/throwcat/server/application.py:164]
2016-05-03 17:17:07,958 WARNING: Uncaught Exception: TypeError("int() argument must be a string or a number, not 'NoneType'",)
Traceback (most recent call last):
  File "/Library/Python/2.7/site-packages/flask/app.py", line 1475, in full_dispatch_request
    rv = self.dispatch_request()
  File "/Library/Python/2.7/site-packages/flask/app.py", line 1461, in dispatch_request
    return self.view_functions[rule.endpoint](**req.view_args)
  File "/Users/majik/github/throwcat/server/utils/api_utils.py", line 22, in decorate
    result = f(*args, **kwargs)
  File "/Users/majik/github/throwcat/server/blueprints/user/controllers.py", line 101, in recovery
    if not check_recovery_captcha(login, captcha):
  File "/Users/majik/github/throwcat/server/blueprints/user/controllers.py", line 210, in check_recovery_captcha
    num = int(current_app.redis.get(key))
TypeError: int() argument must be a string or a number, not 'NoneType'
 [in /Users/majik/github/throwcat/server/application.py:164]
2016-05-03 17:22:57,202 WARNING: Uncaught Exception: KeyError('password_hashs',)
Traceback (most recent call last):
  File "/Library/Python/2.7/site-packages/flask/app.py", line 1475, in full_dispatch_request
    rv = self.dispatch_request()
  File "/Library/Python/2.7/site-packages/flask/app.py", line 1461, in dispatch_request
    return self.view_functions[rule.endpoint](**req.view_args)
  File "/Users/majik/github/throwcat/server/utils/api_utils.py", line 22, in decorate
    result = f(*args, **kwargs)
  File "/Users/majik/github/throwcat/server/blueprints/user/controllers.py", line 143, in login
    if not check_hashed_password(str(user["password_hashs"]), password):
KeyError: 'password_hashs'
 [in /Users/majik/github/throwcat/server/application.py:164]
2016-05-03 17:23:34,562 WARNING: Uncaught Exception: KeyError('password_hash',)
Traceback (most recent call last):
  File "/Library/Python/2.7/site-packages/flask/app.py", line 1475, in full_dispatch_request
    rv = self.dispatch_request()
  File "/Library/Python/2.7/site-packages/flask/app.py", line 1461, in dispatch_request
    return self.view_functions[rule.endpoint](**req.view_args)
  File "/Users/majik/github/throwcat/server/utils/api_utils.py", line 22, in decorate
    result = f(*args, **kwargs)
  File "/Users/majik/github/throwcat/server/blueprints/user/controllers.py", line 146, in login
    return output_user_with_token(user)
  File "/Users/majik/github/throwcat/server/blueprints/user/controllers.py", line 279, in output_user_with_token
    user.update(token=generate_user_token(user))
  File "/Users/majik/github/throwcat/server/blueprints/user/controllers.py", line 232, in generate_user_token
    sha = hmac_sha(user['login'], user['password_hash'])
KeyError: 'password_hash'
 [in /Users/majik/github/throwcat/server/application.py:164]
2016-05-03 17:23:58,406 WARNING: Uncaught Exception: KeyError('password_hash',)
Traceback (most recent call last):
  File "/Library/Python/2.7/site-packages/flask/app.py", line 1475, in full_dispatch_request
    rv = self.dispatch_request()
  File "/Library/Python/2.7/site-packages/flask/app.py", line 1461, in dispatch_request
    return self.view_functions[rule.endpoint](**req.view_args)
  File "/Users/majik/github/throwcat/server/utils/api_utils.py", line 22, in decorate
    result = f(*args, **kwargs)
  File "/Users/majik/github/throwcat/server/blueprints/user/controllers.py", line 146, in login
    return output_user_with_token(user)
  File "/Users/majik/github/throwcat/server/blueprints/user/controllers.py", line 279, in output_user_with_token
    user.update(token=generate_user_token(user))
  File "/Users/majik/github/throwcat/server/blueprints/user/controllers.py", line 232, in generate_user_token
    sha = hmac_sha(user['login'], user['password_hash'])
KeyError: 'password_hash'
 [in /Users/majik/github/throwcat/server/application.py:164]
2016-05-03 17:41:22,775 WARNING: Error: 404
Traceback (most recent call last):
  File "/Library/Python/2.7/site-packages/flask/app.py", line 1475, in full_dispatch_request
    rv = self.dispatch_request()
  File "/Library/Python/2.7/site-packages/flask/app.py", line 1453, in dispatch_request
    self.raise_routing_exception(req)
  File "/Library/Python/2.7/site-packages/flask/app.py", line 1436, in raise_routing_exception
    raise request.routing_exception
NotFound: 404: Not Found
 [in /Users/majik/github/throwcat/server/application.py:141]
2016-05-03 17:41:58,960 WARNING: Error: 404
Traceback (most recent call last):
  File "/Library/Python/2.7/site-packages/flask/app.py", line 1475, in full_dispatch_request
    rv = self.dispatch_request()
  File "/Library/Python/2.7/site-packages/flask/app.py", line 1453, in dispatch_request
    self.raise_routing_exception(req)
  File "/Library/Python/2.7/site-packages/flask/app.py", line 1436, in raise_routing_exception
    raise request.routing_exception
NotFound: 404: Not Found
 [in /Users/majik/github/throwcat/server/application.py:141]
2016-05-03 17:42:42,888 WARNING: Error: 404
Traceback (most recent call last):
  File "/Library/Python/2.7/site-packages/flask/app.py", line 1475, in full_dispatch_request
    rv = self.dispatch_request()
  File "/Library/Python/2.7/site-packages/flask/app.py", line 1453, in dispatch_request
    self.raise_routing_exception(req)
  File "/Library/Python/2.7/site-packages/flask/app.py", line 1436, in raise_routing_exception
    raise request.routing_exception
NotFound: 404: Not Found
 [in /Users/majik/github/throwcat/server/application.py:141]
2016-05-04 03:11:34,023 WARNING: Uncaught Exception: NameError("global name 'send_captcha_by_email' is not defined",)
Traceback (most recent call last):
  File "/Library/Python/2.7/site-packages/flask/app.py", line 1475, in full_dispatch_request
    rv = self.dispatch_request()
  File "/Library/Python/2.7/site-packages/flask/app.py", line 1461, in dispatch_request
    return self.view_functions[rule.endpoint](**req.view_args)
  File "/Users/redy/Sites/throwcat/server/utils/api_utils.py", line 22, in decorate
    result = f(*args, **kwargs)
  File "/Users/redy/Sites/throwcat/server/blueprints/user/controllers/register.py", line 22, in get_register_captcha
    captcha = send_captcha_by_email(login)
NameError: global name 'send_captcha_by_email' is not defined
 [in /Users/redy/Sites/throwcat/server/application.py:164]
2016-05-04 03:12:39,334 WARNING: Uncaught Exception: NameError("global name 'send_register_captcha_by_email' is not defined",)
Traceback (most recent call last):
  File "/Library/Python/2.7/site-packages/flask/app.py", line 1475, in full_dispatch_request
    rv = self.dispatch_request()
  File "/Library/Python/2.7/site-packages/flask/app.py", line 1461, in dispatch_request
    return self.view_functions[rule.endpoint](**req.view_args)
  File "/Users/redy/Sites/throwcat/server/utils/api_utils.py", line 22, in decorate
    result = f(*args, **kwargs)
  File "/Users/redy/Sites/throwcat/server/blueprints/user/controllers/register.py", line 22, in get_register_captcha
    captcha = send_register_captcha_by_email(login)
NameError: global name 'send_register_captcha_by_email' is not defined
 [in /Users/redy/Sites/throwcat/server/application.py:164]
2016-05-04 03:13:15,978 WARNING: Uncaught Exception: NameError("global name 'set_register_captcha' is not defined",)
Traceback (most recent call last):
  File "/Library/Python/2.7/site-packages/flask/app.py", line 1475, in full_dispatch_request
    rv = self.dispatch_request()
  File "/Library/Python/2.7/site-packages/flask/app.py", line 1461, in dispatch_request
    return self.view_functions[rule.endpoint](**req.view_args)
  File "/Users/redy/Sites/throwcat/server/utils/api_utils.py", line 22, in decorate
    result = f(*args, **kwargs)
  File "/Users/redy/Sites/throwcat/server/blueprints/user/controllers/register.py", line 22, in get_register_captcha
    captcha = send_register_captcha_by_email(login)
  File "/Users/redy/Sites/throwcat/server/blueprints/user/helpers.py", line 74, in send_register_captcha_by_email
    captcha = set_register_captcha(email)
NameError: global name 'set_register_captcha' is not defined
 [in /Users/redy/Sites/throwcat/server/application.py:164]
2016-05-04 03:13:40,984 WARNING: Uncaught Exception: NameError("global name 'set_register_captcha' is not defined",)
Traceback (most recent call last):
  File "/Library/Python/2.7/site-packages/flask/app.py", line 1475, in full_dispatch_request
    rv = self.dispatch_request()
  File "/Library/Python/2.7/site-packages/flask/app.py", line 1461, in dispatch_request
    return self.view_functions[rule.endpoint](**req.view_args)
  File "/Users/redy/Sites/throwcat/server/utils/api_utils.py", line 22, in decorate
    result = f(*args, **kwargs)
  File "/Users/redy/Sites/throwcat/server/blueprints/user/controllers/register.py", line 22, in get_register_captcha
    captcha = send_register_captcha_by_email(login)
  File "/Users/redy/Sites/throwcat/server/blueprints/user/helpers.py", line 74, in send_register_captcha_by_email
    captcha = set_register_captcha(email)
NameError: global name 'set_register_captcha' is not defined
 [in /Users/redy/Sites/throwcat/server/application.py:164]
2016-05-04 03:16:06,740 WARNING: Uncaught Exception: NameError("global name 'set_register_captcha' is not defined",)
Traceback (most recent call last):
  File "/Library/Python/2.7/site-packages/flask/app.py", line 1475, in full_dispatch_request
    rv = self.dispatch_request()
  File "/Library/Python/2.7/site-packages/flask/app.py", line 1461, in dispatch_request
    return self.view_functions[rule.endpoint](**req.view_args)
  File "/Users/redy/Sites/throwcat/server/utils/api_utils.py", line 22, in decorate
    result = f(*args, **kwargs)
  File "/Users/redy/Sites/throwcat/server/blueprints/user/controllers/register.py", line 22, in get_register_captcha
    captcha = send_register_captcha_by_email(login)
  File "/Users/redy/Sites/throwcat/server/blueprints/user/helpers.py", line 74, in send_register_captcha_by_email
    captcha = set_register_captcha(email)
NameError: global name 'set_register_captcha' is not defined
 [in /Users/redy/Sites/throwcat/server/application.py:164]
2016-05-04 03:16:15,384 WARNING: Uncaught Exception: NameError("global name 'set_register_captcha' is not defined",)
Traceback (most recent call last):
  File "/Library/Python/2.7/site-packages/flask/app.py", line 1475, in full_dispatch_request
    rv = self.dispatch_request()
  File "/Library/Python/2.7/site-packages/flask/app.py", line 1461, in dispatch_request
    return self.view_functions[rule.endpoint](**req.view_args)
  File "/Users/redy/Sites/throwcat/server/utils/api_utils.py", line 22, in decorate
    result = f(*args, **kwargs)
  File "/Users/redy/Sites/throwcat/server/blueprints/user/controllers/register.py", line 22, in get_register_captcha
    captcha = send_register_captcha_by_email(login)
  File "/Users/redy/Sites/throwcat/server/blueprints/user/helpers.py", line 74, in send_register_captcha_by_email
    captcha = set_register_captcha(email)
NameError: global name 'set_register_captcha' is not defined
 [in /Users/redy/Sites/throwcat/server/application.py:164]
2016-05-04 03:18:18,129 WARNING: Uncaught Exception: ValueError('substring not found',)
Traceback (most recent call last):
  File "/Library/Python/2.7/site-packages/flask/app.py", line 1475, in full_dispatch_request
    rv = self.dispatch_request()
  File "/Library/Python/2.7/site-packages/flask/app.py", line 1461, in dispatch_request
    return self.view_functions[rule.endpoint](**req.view_args)
  File "/Users/redy/Sites/throwcat/server/utils/api_utils.py", line 22, in decorate
    result = f(*args, **kwargs)
  File "/Users/redy/Sites/throwcat/server/blueprints/user/controllers/register.py", line 46, in register
    if not check_register_captcha(login, captcha):
  File "/Users/redy/Sites/throwcat/server/blueprints/user/helpers.py", line 27, in check_register_captcha
    return check_random_string(int(num), captcha)
  File "/Users/redy/Sites/throwcat/server/utils/helpers.py", line 292, in check_random_string
    return random_num == short_url.decode_url(random_str)
  File "/Library/Python/2.7/site-packages/short_url/__init__.py", line 135, in decode_url
    return DEFAULT_ENCODER.decode_url(n)
  File "/Library/Python/2.7/site-packages/short_url/__init__.py", line 71, in decode_url
    return self.decode(self.debase(n))
  File "/Library/Python/2.7/site-packages/short_url/__init__.py", line 108, in debase
    result += self.alphabet.index(c) * (n ** i)
ValueError: substring not found
 [in /Users/redy/Sites/throwcat/server/application.py:164]
2016-05-04 03:19:11,116 WARNING: Uncaught Exception: ValueError('substring not found',)
Traceback (most recent call last):
  File "/Library/Python/2.7/site-packages/flask/app.py", line 1475, in full_dispatch_request
    rv = self.dispatch_request()
  File "/Library/Python/2.7/site-packages/flask/app.py", line 1461, in dispatch_request
    return self.view_functions[rule.endpoint](**req.view_args)
  File "/Users/redy/Sites/throwcat/server/utils/api_utils.py", line 22, in decorate
    result = f(*args, **kwargs)
  File "/Users/redy/Sites/throwcat/server/blueprints/user/controllers/register.py", line 46, in register
    if not check_register_captcha(login, captcha):
  File "/Users/redy/Sites/throwcat/server/blueprints/user/helpers.py", line 27, in check_register_captcha
    return check_random_string(int(num), captcha)
  File "/Users/redy/Sites/throwcat/server/utils/helpers.py", line 293, in check_random_string
    return random_num == short_url.decode_url(random_str)
  File "/Library/Python/2.7/site-packages/short_url/__init__.py", line 135, in decode_url
    return DEFAULT_ENCODER.decode_url(n)
  File "/Library/Python/2.7/site-packages/short_url/__init__.py", line 71, in decode_url
    return self.decode(self.debase(n))
  File "/Library/Python/2.7/site-packages/short_url/__init__.py", line 108, in debase
    result += self.alphabet.index(c) * (n ** i)
ValueError: substring not found
 [in /Users/redy/Sites/throwcat/server/application.py:164]
2016-05-04 03:28:01,402 WARNING: Uncaught Exception: TypeError("unsupported operand type(s) for &: 'str' and 'int'",)
Traceback (most recent call last):
  File "/Library/Python/2.7/site-packages/flask/app.py", line 1475, in full_dispatch_request
    rv = self.dispatch_request()
  File "/Library/Python/2.7/site-packages/flask/app.py", line 1461, in dispatch_request
    return self.view_functions[rule.endpoint](**req.view_args)
  File "/Users/redy/Sites/throwcat/server/utils/api_utils.py", line 22, in decorate
    result = f(*args, **kwargs)
  File "/Users/redy/Sites/throwcat/server/blueprints/user/controllers/register.py", line 22, in get_register_captcha
    captcha = send_register_captcha_by_email(login)
  File "/Users/redy/Sites/throwcat/server/blueprints/user/helpers.py", line 74, in send_register_captcha_by_email
    captcha = set_register_captcha(email)
  File "/Users/redy/Sites/throwcat/server/blueprints/user/helpers.py", line 17, in set_register_captcha
    num, captcha = random_string(stored_num, length=6)
  File "/Users/redy/Sites/throwcat/server/utils/helpers.py", line 285, in random_string
    random_str = short_url.encode_url(random_num, length)
  File "/Library/Python/2.7/site-packages/short_url/__init__.py", line 131, in encode_url
    return DEFAULT_ENCODER.encode_url(n, min_length)
  File "/Library/Python/2.7/site-packages/short_url/__init__.py", line 68, in encode_url
    return self.enbase(self.encode(n), min_length)
  File "/Library/Python/2.7/site-packages/short_url/__init__.py", line 74, in encode
    return (n & ~self.mask) | self._encode(n & self.mask)
TypeError: unsupported operand type(s) for &: 'str' and 'int'
 [in /Users/redy/Sites/throwcat/server/application.py:164]
2016-05-04 03:29:12,986 WARNING: Uncaught Exception: TypeError("unsupported operand type(s) for &: 'str' and 'int'",)
Traceback (most recent call last):
  File "/Library/Python/2.7/site-packages/flask/app.py", line 1475, in full_dispatch_request
    rv = self.dispatch_request()
  File "/Library/Python/2.7/site-packages/flask/app.py", line 1461, in dispatch_request
    return self.view_functions[rule.endpoint](**req.view_args)
  File "/Users/redy/Sites/throwcat/server/utils/api_utils.py", line 22, in decorate
    result = f(*args, **kwargs)
  File "/Users/redy/Sites/throwcat/server/blueprints/user/controllers/register.py", line 22, in get_register_captcha
    captcha = send_register_captcha_by_email(login)
  File "/Users/redy/Sites/throwcat/server/blueprints/user/helpers.py", line 74, in send_register_captcha_by_email
    captcha = set_register_captcha(email)
  File "/Users/redy/Sites/throwcat/server/blueprints/user/helpers.py", line 17, in set_register_captcha
    num, captcha = random_string(stored_num, length=6)
  File "/Users/redy/Sites/throwcat/server/utils/helpers.py", line 287, in random_string
    random_str = short_url.encode_url(random_num, length)
  File "/Library/Python/2.7/site-packages/short_url/__init__.py", line 131, in encode_url
    return DEFAULT_ENCODER.encode_url(n, min_length)
  File "/Library/Python/2.7/site-packages/short_url/__init__.py", line 68, in encode_url
    return self.enbase(self.encode(n), min_length)
  File "/Library/Python/2.7/site-packages/short_url/__init__.py", line 74, in encode
    return (n & ~self.mask) | self._encode(n & self.mask)
TypeError: unsupported operand type(s) for &: 'str' and 'int'
 [in /Users/redy/Sites/throwcat/server/application.py:164]
2016-05-04 03:29:47,831 WARNING: Uncaught Exception: TypeError("unsupported operand type(s) for &: 'str' and 'int'",)
Traceback (most recent call last):
  File "/Library/Python/2.7/site-packages/flask/app.py", line 1475, in full_dispatch_request
    rv = self.dispatch_request()
  File "/Library/Python/2.7/site-packages/flask/app.py", line 1461, in dispatch_request
    return self.view_functions[rule.endpoint](**req.view_args)
  File "/Users/redy/Sites/throwcat/server/utils/api_utils.py", line 22, in decorate
    result = f(*args, **kwargs)
  File "/Users/redy/Sites/throwcat/server/blueprints/user/controllers/register.py", line 22, in get_register_captcha
    captcha = send_register_captcha_by_email(login)
  File "/Users/redy/Sites/throwcat/server/blueprints/user/helpers.py", line 74, in send_register_captcha_by_email
    captcha = set_register_captcha(email)
  File "/Users/redy/Sites/throwcat/server/blueprints/user/helpers.py", line 17, in set_register_captcha
    num, captcha = random_string(stored_num, length=6)
  File "/Users/redy/Sites/throwcat/server/utils/helpers.py", line 288, in random_string
    random_str = short_url.encode_url(random_num, length)
  File "/Library/Python/2.7/site-packages/short_url/__init__.py", line 131, in encode_url
    return DEFAULT_ENCODER.encode_url(n, min_length)
  File "/Library/Python/2.7/site-packages/short_url/__init__.py", line 68, in encode_url
    return self.enbase(self.encode(n), min_length)
  File "/Library/Python/2.7/site-packages/short_url/__init__.py", line 74, in encode
    return (n & ~self.mask) | self._encode(n & self.mask)
TypeError: unsupported operand type(s) for &: 'str' and 'int'
 [in /Users/redy/Sites/throwcat/server/application.py:164]
2016-05-04 03:30:03,250 WARNING: Uncaught Exception: TypeError("unsupported operand type(s) for &: 'str' and 'int'",)
Traceback (most recent call last):
  File "/Library/Python/2.7/site-packages/flask/app.py", line 1475, in full_dispatch_request
    rv = self.dispatch_request()
  File "/Library/Python/2.7/site-packages/flask/app.py", line 1461, in dispatch_request
    return self.view_functions[rule.endpoint](**req.view_args)
  File "/Users/redy/Sites/throwcat/server/utils/api_utils.py", line 22, in decorate
    result = f(*args, **kwargs)
  File "/Users/redy/Sites/throwcat/server/blueprints/user/controllers/register.py", line 22, in get_register_captcha
    captcha = send_register_captcha_by_email(login)
  File "/Users/redy/Sites/throwcat/server/blueprints/user/helpers.py", line 74, in send_register_captcha_by_email
    captcha = set_register_captcha(email)
  File "/Users/redy/Sites/throwcat/server/blueprints/user/helpers.py", line 17, in set_register_captcha
    num, captcha = random_string(stored_num, length=6)
  File "/Users/redy/Sites/throwcat/server/utils/helpers.py", line 288, in random_string
    random_str = short_url.encode_url(random_num, length)
  File "/Library/Python/2.7/site-packages/short_url/__init__.py", line 131, in encode_url
    return DEFAULT_ENCODER.encode_url(n, min_length)
  File "/Library/Python/2.7/site-packages/short_url/__init__.py", line 68, in encode_url
    return self.enbase(self.encode(n), min_length)
  File "/Library/Python/2.7/site-packages/short_url/__init__.py", line 74, in encode
    return (n & ~self.mask) | self._encode(n & self.mask)
TypeError: unsupported operand type(s) for &: 'str' and 'int'
 [in /Users/redy/Sites/throwcat/server/application.py:164]
2016-05-04 04:05:37,145 WARNING: Error: 404
Traceback (most recent call last):
  File "/Library/Python/2.7/site-packages/flask/app.py", line 1475, in full_dispatch_request
    rv = self.dispatch_request()
  File "/Library/Python/2.7/site-packages/flask/app.py", line 1453, in dispatch_request
    self.raise_routing_exception(req)
  File "/Library/Python/2.7/site-packages/flask/app.py", line 1436, in raise_routing_exception
    raise request.routing_exception
NotFound: 404: Not Found
 [in /Users/redy/Sites/throwcat/server/application.py:141]
2016-05-04 04:13:36,511 WARNING: Uncaught Exception: TypeError("int() argument must be a string or a number, not 'NoneType'",)
Traceback (most recent call last):
  File "/Library/Python/2.7/site-packages/flask/app.py", line 1475, in full_dispatch_request
    rv = self.dispatch_request()
  File "/Library/Python/2.7/site-packages/flask/app.py", line 1461, in dispatch_request
    return self.view_functions[rule.endpoint](**req.view_args)
  File "/Users/redy/Sites/throwcat/server/utils/api_utils.py", line 22, in decorate
    result = f(*args, **kwargs)
  File "/Users/redy/Sites/throwcat/server/blueprints/user/controllers/recovery.py", line 46, in recovery
    if not check_recovery_captcha(login, captcha):
  File "/Users/redy/Sites/throwcat/server/blueprints/user/helpers.py", line 50, in check_recovery_captcha
    return check_random_string(int(num), captcha)
TypeError: int() argument must be a string or a number, not 'NoneType'
 [in /Users/redy/Sites/throwcat/server/application.py:164]
2016-05-04 04:14:23,153 WARNING: Uncaught Exception: TypeError("int() argument must be a string or a number, not 'NoneType'",)
Traceback (most recent call last):
  File "/Library/Python/2.7/site-packages/flask/app.py", line 1475, in full_dispatch_request
    rv = self.dispatch_request()
  File "/Library/Python/2.7/site-packages/flask/app.py", line 1461, in dispatch_request
    return self.view_functions[rule.endpoint](**req.view_args)
  File "/Users/redy/Sites/throwcat/server/utils/api_utils.py", line 22, in decorate
    result = f(*args, **kwargs)
  File "/Users/redy/Sites/throwcat/server/blueprints/user/controllers/recovery.py", line 46, in recovery
    if not check_recovery_captcha(login, captcha):
  File "/Users/redy/Sites/throwcat/server/blueprints/user/helpers.py", line 50, in check_recovery_captcha
    return check_random_string(int(num), captcha)
TypeError: int() argument must be a string or a number, not 'NoneType'
 [in /Users/redy/Sites/throwcat/server/application.py:164]
2016-05-04 04:19:13,562 WARNING: Uncaught Exception: NameError("global name 'new_password' is not defined",)
Traceback (most recent call last):
  File "/Library/Python/2.7/site-packages/flask/app.py", line 1475, in full_dispatch_request
    rv = self.dispatch_request()
  File "/Library/Python/2.7/site-packages/flask/app.py", line 1461, in dispatch_request
    return self.view_functions[rule.endpoint](**req.view_args)
  File "/Users/redy/Sites/throwcat/server/utils/api_utils.py", line 22, in decorate
    result = f(*args, **kwargs)
  File "/Users/redy/Sites/throwcat/server/blueprints/user/controllers/recovery.py", line 54, in recovery
    user["password_hash"] = generate_hashed_password(new_password)
NameError: global name 'new_password' is not defined
 [in /Users/redy/Sites/throwcat/server/application.py:164]
2016-05-04 04:20:18,281 WARNING: Error: 404
Traceback (most recent call last):
  File "/Library/Python/2.7/site-packages/flask/app.py", line 1475, in full_dispatch_request
    rv = self.dispatch_request()
  File "/Library/Python/2.7/site-packages/flask/app.py", line 1453, in dispatch_request
    self.raise_routing_exception(req)
  File "/Library/Python/2.7/site-packages/flask/app.py", line 1436, in raise_routing_exception
    raise request.routing_exception
NotFound: 404: Not Found
 [in /Users/redy/Sites/throwcat/server/application.py:141]
2016-05-04 04:34:37,452 WARNING: Error: 405
Traceback (most recent call last):
  File "/Library/Python/2.7/site-packages/flask/app.py", line 1475, in full_dispatch_request
    rv = self.dispatch_request()
  File "/Library/Python/2.7/site-packages/flask/app.py", line 1453, in dispatch_request
    self.raise_routing_exception(req)
  File "/Library/Python/2.7/site-packages/flask/app.py", line 1436, in raise_routing_exception
    raise request.routing_exception
MethodNotAllowed: 405: Method Not Allowed
 [in /Users/redy/Sites/throwcat/server/application.py:148]
2016-05-04 04:36:11,811 WARNING: Error: 404
Traceback (most recent call last):
  File "/Library/Python/2.7/site-packages/flask/app.py", line 1475, in full_dispatch_request
    rv = self.dispatch_request()
  File "/Library/Python/2.7/site-packages/flask/app.py", line 1453, in dispatch_request
    self.raise_routing_exception(req)
  File "/Library/Python/2.7/site-packages/flask/app.py", line 1436, in raise_routing_exception
    raise request.routing_exception
NotFound: 404: Not Found
 [in /Users/redy/Sites/throwcat/server/application.py:141]
2016-05-04 04:36:14,585 WARNING: Error: 405
Traceback (most recent call last):
  File "/Library/Python/2.7/site-packages/flask/app.py", line 1475, in full_dispatch_request
    rv = self.dispatch_request()
  File "/Library/Python/2.7/site-packages/flask/app.py", line 1453, in dispatch_request
    self.raise_routing_exception(req)
  File "/Library/Python/2.7/site-packages/flask/app.py", line 1436, in raise_routing_exception
    raise request.routing_exception
MethodNotAllowed: 405: Method Not Allowed
 [in /Users/redy/Sites/throwcat/server/application.py:148]
2016-05-04 04:36:21,046 WARNING: Error: 405
Traceback (most recent call last):
  File "/Library/Python/2.7/site-packages/flask/app.py", line 1475, in full_dispatch_request
    rv = self.dispatch_request()
  File "/Library/Python/2.7/site-packages/flask/app.py", line 1453, in dispatch_request
    self.raise_routing_exception(req)
  File "/Library/Python/2.7/site-packages/flask/app.py", line 1436, in raise_routing_exception
    raise request.routing_exception
MethodNotAllowed: 405: Method Not Allowed
 [in /Users/redy/Sites/throwcat/server/application.py:148]
2016-05-04 05:18:32,341 WARNING: Error: 404
Traceback (most recent call last):
  File "/Library/Python/2.7/site-packages/flask/app.py", line 1475, in full_dispatch_request
    rv = self.dispatch_request()
  File "/Library/Python/2.7/site-packages/flask/app.py", line 1453, in dispatch_request
    self.raise_routing_exception(req)
  File "/Library/Python/2.7/site-packages/flask/app.py", line 1436, in raise_routing_exception
    raise request.routing_exception
NotFound: 404: Not Found
 [in /Users/redy/Sites/throwcat/server/application.py:141]
2016-05-04 05:24:33,618 WARNING: Error: 404
Traceback (most recent call last):
  File "/Library/Python/2.7/site-packages/flask/app.py", line 1475, in full_dispatch_request
    rv = self.dispatch_request()
  File "/Library/Python/2.7/site-packages/flask/app.py", line 1453, in dispatch_request
    self.raise_routing_exception(req)
  File "/Library/Python/2.7/site-packages/flask/app.py", line 1436, in raise_routing_exception
    raise request.routing_exception
NotFound: 404: Not Found
 [in /Users/redy/Sites/throwcat/server/application.py:141]
2016-05-04 05:25:03,715 WARNING: Error: 404
Traceback (most recent call last):
  File "/Library/Python/2.7/site-packages/flask/app.py", line 1475, in full_dispatch_request
    rv = self.dispatch_request()
  File "/Library/Python/2.7/site-packages/flask/app.py", line 1453, in dispatch_request
    self.raise_routing_exception(req)
  File "/Library/Python/2.7/site-packages/flask/app.py", line 1436, in raise_routing_exception
    raise request.routing_exception
NotFound: 404: Not Found
 [in /Users/redy/Sites/throwcat/server/application.py:141]
2016-05-04 05:25:45,231 WARNING: Error: 404
Traceback (most recent call last):
  File "/Library/Python/2.7/site-packages/flask/app.py", line 1475, in full_dispatch_request
    rv = self.dispatch_request()
  File "/Library/Python/2.7/site-packages/flask/app.py", line 1453, in dispatch_request
    self.raise_routing_exception(req)
  File "/Library/Python/2.7/site-packages/flask/app.py", line 1436, in raise_routing_exception
    raise request.routing_exception
NotFound: 404: Not Found
 [in /Users/redy/Sites/throwcat/server/application.py:141]
2016-05-04 05:26:24,859 WARNING: Error: 404
Traceback (most recent call last):
  File "/Library/Python/2.7/site-packages/flask/app.py", line 1475, in full_dispatch_request
    rv = self.dispatch_request()
  File "/Library/Python/2.7/site-packages/flask/app.py", line 1453, in dispatch_request
    self.raise_routing_exception(req)
  File "/Library/Python/2.7/site-packages/flask/app.py", line 1436, in raise_routing_exception
    raise request.routing_exception
NotFound: 404: Not Found
 [in /Users/redy/Sites/throwcat/server/application.py:141]
2016-05-04 05:26:26,669 WARNING: Error: 404
Traceback (most recent call last):
  File "/Library/Python/2.7/site-packages/flask/app.py", line 1475, in full_dispatch_request
    rv = self.dispatch_request()
  File "/Library/Python/2.7/site-packages/flask/app.py", line 1453, in dispatch_request
    self.raise_routing_exception(req)
  File "/Library/Python/2.7/site-packages/flask/app.py", line 1436, in raise_routing_exception
    raise request.routing_exception
NotFound: 404: Not Found
 [in /Users/redy/Sites/throwcat/server/application.py:141]
2016-05-04 05:26:28,571 WARNING: Error: 404
Traceback (most recent call last):
  File "/Library/Python/2.7/site-packages/flask/app.py", line 1475, in full_dispatch_request
    rv = self.dispatch_request()
  File "/Library/Python/2.7/site-packages/flask/app.py", line 1453, in dispatch_request
    self.raise_routing_exception(req)
  File "/Library/Python/2.7/site-packages/flask/app.py", line 1436, in raise_routing_exception
    raise request.routing_exception
NotFound: 404: Not Found
 [in /Users/redy/Sites/throwcat/server/application.py:141]
2016-05-04 05:28:08,772 WARNING: Error: 404
Traceback (most recent call last):
  File "/Library/Python/2.7/site-packages/flask/app.py", line 1475, in full_dispatch_request
    rv = self.dispatch_request()
  File "/Library/Python/2.7/site-packages/flask/app.py", line 1453, in dispatch_request
    self.raise_routing_exception(req)
  File "/Library/Python/2.7/site-packages/flask/app.py", line 1436, in raise_routing_exception
    raise request.routing_exception
NotFound: 404: Not Found
 [in /Users/redy/Sites/throwcat/server/application.py:141]
2016-05-04 05:28:57,539 WARNING: Error: 404
Traceback (most recent call last):
  File "/Library/Python/2.7/site-packages/flask/app.py", line 1475, in full_dispatch_request
    rv = self.dispatch_request()
  File "/Library/Python/2.7/site-packages/flask/app.py", line 1453, in dispatch_request
    self.raise_routing_exception(req)
  File "/Library/Python/2.7/site-packages/flask/app.py", line 1436, in raise_routing_exception
    raise request.routing_exception
NotFound: 404: Not Found
 [in /Users/redy/Sites/throwcat/server/application.py:141]
2016-05-04 05:29:18,553 WARNING: Error: 404
Traceback (most recent call last):
  File "/Library/Python/2.7/site-packages/flask/app.py", line 1475, in full_dispatch_request
    rv = self.dispatch_request()
  File "/Library/Python/2.7/site-packages/flask/app.py", line 1453, in dispatch_request
    self.raise_routing_exception(req)
  File "/Library/Python/2.7/site-packages/flask/app.py", line 1436, in raise_routing_exception
    raise request.routing_exception
NotFound: 404: Not Found
 [in /Users/redy/Sites/throwcat/server/application.py:141]
2016-05-04 05:31:04,923 WARNING: Error: 404
Traceback (most recent call last):
  File "/Library/Python/2.7/site-packages/flask/app.py", line 1475, in full_dispatch_request
    rv = self.dispatch_request()
  File "/Library/Python/2.7/site-packages/flask/app.py", line 1453, in dispatch_request
    self.raise_routing_exception(req)
  File "/Library/Python/2.7/site-packages/flask/app.py", line 1436, in raise_routing_exception
    raise request.routing_exception
NotFound: 404: Not Found
 [in /Users/redy/Sites/throwcat/server/application.py:141]
2016-05-04 05:31:08,582 WARNING: Error: 404
Traceback (most recent call last):
  File "/Library/Python/2.7/site-packages/flask/app.py", line 1475, in full_dispatch_request
    rv = self.dispatch_request()
  File "/Library/Python/2.7/site-packages/flask/app.py", line 1453, in dispatch_request
    self.raise_routing_exception(req)
  File "/Library/Python/2.7/site-packages/flask/app.py", line 1436, in raise_routing_exception
    raise request.routing_exception
NotFound: 404: Not Found
 [in /Users/redy/Sites/throwcat/server/application.py:141]
2016-05-04 05:33:49,872 WARNING: Error: 404
Traceback (most recent call last):
  File "/Library/Python/2.7/site-packages/flask/app.py", line 1475, in full_dispatch_request
    rv = self.dispatch_request()
  File "/Library/Python/2.7/site-packages/flask/app.py", line 1453, in dispatch_request
    self.raise_routing_exception(req)
  File "/Library/Python/2.7/site-packages/flask/app.py", line 1436, in raise_routing_exception
    raise request.routing_exception
NotFound: 404: Not Found
 [in /Users/redy/Sites/throwcat/server/application.py:141]
2016-05-04 05:35:13,747 WARNING: Error: 404
Traceback (most recent call last):
  File "/Library/Python/2.7/site-packages/flask/app.py", line 1475, in full_dispatch_request
    rv = self.dispatch_request()
  File "/Library/Python/2.7/site-packages/flask/app.py", line 1453, in dispatch_request
    self.raise_routing_exception(req)
  File "/Library/Python/2.7/site-packages/flask/app.py", line 1436, in raise_routing_exception
    raise request.routing_exception
NotFound: 404: Not Found
 [in /Users/redy/Sites/throwcat/server/application.py:141]
2016-05-04 05:35:52,272 WARNING: Error: 404
Traceback (most recent call last):
  File "/Library/Python/2.7/site-packages/flask/app.py", line 1475, in full_dispatch_request
    rv = self.dispatch_request()
  File "/Library/Python/2.7/site-packages/flask/app.py", line 1453, in dispatch_request
    self.raise_routing_exception(req)
  File "/Library/Python/2.7/site-packages/flask/app.py", line 1436, in raise_routing_exception
    raise request.routing_exception
NotFound: 404: Not Found
 [in /Users/redy/Sites/throwcat/server/application.py:141]
2016-05-04 05:37:11,720 WARNING: Error: 404
Traceback (most recent call last):
  File "/Library/Python/2.7/site-packages/flask/app.py", line 1475, in full_dispatch_request
    rv = self.dispatch_request()
  File "/Library/Python/2.7/site-packages/flask/app.py", line 1453, in dispatch_request
    self.raise_routing_exception(req)
  File "/Library/Python/2.7/site-packages/flask/app.py", line 1436, in raise_routing_exception
    raise request.routing_exception
NotFound: 404: Not Found
 [in /Users/redy/Sites/throwcat/server/application.py:141]
2016-05-04 05:51:11,071 WARNING: Error: 404
Traceback (most recent call last):
  File "/Library/Python/2.7/site-packages/flask/app.py", line 1475, in full_dispatch_request
    rv = self.dispatch_request()
  File "/Library/Python/2.7/site-packages/flask/app.py", line 1453, in dispatch_request
    self.raise_routing_exception(req)
  File "/Library/Python/2.7/site-packages/flask/app.py", line 1436, in raise_routing_exception
    raise request.routing_exception
NotFound: 404: Not Found
 [in /Users/redy/Sites/throwcat/server/application.py:141]
2016-05-04 05:51:14,923 WARNING: Error: 404
Traceback (most recent call last):
  File "/Library/Python/2.7/site-packages/flask/app.py", line 1475, in full_dispatch_request
    rv = self.dispatch_request()
  File "/Library/Python/2.7/site-packages/flask/app.py", line 1453, in dispatch_request
    self.raise_routing_exception(req)
  File "/Library/Python/2.7/site-packages/flask/app.py", line 1436, in raise_routing_exception
    raise request.routing_exception
NotFound: 404: Not Found
 [in /Users/redy/Sites/throwcat/server/application.py:141]
2016-05-04 05:51:55,683 WARNING: Error: 404
Traceback (most recent call last):
  File "/Library/Python/2.7/site-packages/flask/app.py", line 1475, in full_dispatch_request
    rv = self.dispatch_request()
  File "/Library/Python/2.7/site-packages/flask/app.py", line 1453, in dispatch_request
    self.raise_routing_exception(req)
  File "/Library/Python/2.7/site-packages/flask/app.py", line 1436, in raise_routing_exception
    raise request.routing_exception
NotFound: 404: Not Found
 [in /Users/redy/Sites/throwcat/server/application.py:141]
2016-05-04 06:23:11,821 WARNING: Error: 404
Traceback (most recent call last):
  File "/Library/Python/2.7/site-packages/flask/app.py", line 1475, in full_dispatch_request
    rv = self.dispatch_request()
  File "/Library/Python/2.7/site-packages/flask/app.py", line 1453, in dispatch_request
    self.raise_routing_exception(req)
  File "/Library/Python/2.7/site-packages/flask/app.py", line 1436, in raise_routing_exception
    raise request.routing_exception
NotFound: 404: Not Found
 [in /Users/redy/Sites/throwcat/server/application.py:141]
2016-05-04 06:25:02,015 WARNING: Error: 404
Traceback (most recent call last):
  File "/Library/Python/2.7/site-packages/flask/app.py", line 1475, in full_dispatch_request
    rv = self.dispatch_request()
  File "/Library/Python/2.7/site-packages/flask/app.py", line 1453, in dispatch_request
    self.raise_routing_exception(req)
  File "/Library/Python/2.7/site-packages/flask/app.py", line 1436, in raise_routing_exception
    raise request.routing_exception
NotFound: 404: Not Found
 [in /Users/redy/Sites/throwcat/server/application.py:141]
2016-05-04 06:26:20,812 WARNING: Error: 404
Traceback (most recent call last):
  File "/Library/Python/2.7/site-packages/flask/app.py", line 1475, in full_dispatch_request
    rv = self.dispatch_request()
  File "/Library/Python/2.7/site-packages/flask/app.py", line 1453, in dispatch_request
    self.raise_routing_exception(req)
  File "/Library/Python/2.7/site-packages/flask/app.py", line 1436, in raise_routing_exception
    raise request.routing_exception
NotFound: 404: Not Found
 [in /Users/redy/Sites/throwcat/server/application.py:141]
2016-05-04 06:57:03,462 WARNING: Error: 404
Traceback (most recent call last):
  File "/Library/Python/2.7/site-packages/flask/app.py", line 1475, in full_dispatch_request
    rv = self.dispatch_request()
  File "/Library/Python/2.7/site-packages/flask/app.py", line 1453, in dispatch_request
    self.raise_routing_exception(req)
  File "/Library/Python/2.7/site-packages/flask/app.py", line 1436, in raise_routing_exception
    raise request.routing_exception
NotFound: 404: Not Found
 [in /Users/redy/Sites/throwcat/server/application.py:141]
2016-05-04 06:57:41,360 WARNING: Error: 404
Traceback (most recent call last):
  File "/Library/Python/2.7/site-packages/flask/app.py", line 1475, in full_dispatch_request
    rv = self.dispatch_request()
  File "/Library/Python/2.7/site-packages/flask/app.py", line 1453, in dispatch_request
    self.raise_routing_exception(req)
  File "/Library/Python/2.7/site-packages/flask/app.py", line 1436, in raise_routing_exception
    raise request.routing_exception
NotFound: 404: Not Found
 [in /Users/redy/Sites/throwcat/server/application.py:141]
2016-05-04 06:58:35,319 WARNING: Error: 404
Traceback (most recent call last):
  File "/Library/Python/2.7/site-packages/flask/app.py", line 1475, in full_dispatch_request
    rv = self.dispatch_request()
  File "/Library/Python/2.7/site-packages/flask/app.py", line 1453, in dispatch_request
    self.raise_routing_exception(req)
  File "/Library/Python/2.7/site-packages/flask/app.py", line 1436, in raise_routing_exception
    raise request.routing_exception
NotFound: 404: Not Found
 [in /Users/redy/Sites/throwcat/server/application.py:141]
2016-05-04 06:58:45,650 WARNING: Error: 404
Traceback (most recent call last):
  File "/Library/Python/2.7/site-packages/flask/app.py", line 1475, in full_dispatch_request
    rv = self.dispatch_request()
  File "/Library/Python/2.7/site-packages/flask/app.py", line 1453, in dispatch_request
    self.raise_routing_exception(req)
  File "/Library/Python/2.7/site-packages/flask/app.py", line 1436, in raise_routing_exception
    raise request.routing_exception
NotFound: 404: Not Found
 [in /Users/redy/Sites/throwcat/server/application.py:141]
2016-05-04 06:58:59,416 WARNING: Error: 404
Traceback (most recent call last):
  File "/Library/Python/2.7/site-packages/flask/app.py", line 1475, in full_dispatch_request
    rv = self.dispatch_request()
  File "/Library/Python/2.7/site-packages/flask/app.py", line 1453, in dispatch_request
    self.raise_routing_exception(req)
  File "/Library/Python/2.7/site-packages/flask/app.py", line 1436, in raise_routing_exception
    raise request.routing_exception
NotFound: 404: Not Found
 [in /Users/redy/Sites/throwcat/server/application.py:141]
2016-05-04 07:02:05,151 WARNING: Error: 404
Traceback (most recent call last):
  File "/Library/Python/2.7/site-packages/flask/app.py", line 1475, in full_dispatch_request
    rv = self.dispatch_request()
  File "/Library/Python/2.7/site-packages/flask/app.py", line 1453, in dispatch_request
    self.raise_routing_exception(req)
  File "/Library/Python/2.7/site-packages/flask/app.py", line 1436, in raise_routing_exception
    raise request.routing_exception
NotFound: 404: Not Found
 [in /Users/redy/Sites/throwcat/server/application.py:141]
2016-05-04 07:02:05,319 WARNING: Error: 404
Traceback (most recent call last):
  File "/Library/Python/2.7/site-packages/flask/app.py", line 1475, in full_dispatch_request
    rv = self.dispatch_request()
  File "/Library/Python/2.7/site-packages/flask/app.py", line 1453, in dispatch_request
    self.raise_routing_exception(req)
  File "/Library/Python/2.7/site-packages/flask/app.py", line 1436, in raise_routing_exception
    raise request.routing_exception
NotFound: 404: Not Found
 [in /Users/redy/Sites/throwcat/server/application.py:141]
2016-05-04 07:04:07,913 WARNING: Error: 404
Traceback (most recent call last):
  File "/Library/Python/2.7/site-packages/flask/app.py", line 1475, in full_dispatch_request
    rv = self.dispatch_request()
  File "/Library/Python/2.7/site-packages/flask/app.py", line 1453, in dispatch_request
    self.raise_routing_exception(req)
  File "/Library/Python/2.7/site-packages/flask/app.py", line 1436, in raise_routing_exception
    raise request.routing_exception
NotFound: 404: Not Found
 [in /Users/redy/Sites/throwcat/server/application.py:141]
2016-05-04 07:04:09,085 WARNING: Error: 404
Traceback (most recent call last):
  File "/Library/Python/2.7/site-packages/flask/app.py", line 1475, in full_dispatch_request
    rv = self.dispatch_request()
  File "/Library/Python/2.7/site-packages/flask/app.py", line 1453, in dispatch_request
    self.raise_routing_exception(req)
  File "/Library/Python/2.7/site-packages/flask/app.py", line 1436, in raise_routing_exception
    raise request.routing_exception
NotFound: 404: Not Found
 [in /Users/redy/Sites/throwcat/server/application.py:141]
2016-05-04 07:15:09,503 WARNING: Uncaught Exception: TypeError(u"'Collection' object is not callable. If you meant to call the 'find_by_oid_scope' method on a 'Collection' object it is failing because no such method exists.\nIf 'find_by_oid_scope' is a Document then you may have forgotten to register it to the connection.",)
Traceback (most recent call last):
  File "/Library/Python/2.7/site-packages/flask/app.py", line 1475, in full_dispatch_request
    rv = self.dispatch_request()
  File "/Library/Python/2.7/site-packages/flask/app.py", line 1461, in dispatch_request
    return self.view_functions[rule.endpoint](**req.view_args)
  File "/Users/redy/Sites/throwcat/server/utils/api_utils.py", line 22, in decorate
    result = f(*args, **kwargs)
  File "/Users/redy/Sites/throwcat/server/blueprints/media/controllers/base.py", line 39, in list_media
    Media.find_by_oid_scope(user['_id'], scope)
  File "/Library/Python/2.7/site-packages/mongokit/collection.py", line 75, in __call__
    "register it to the connection." % (name, name))
TypeError: 'Collection' object is not callable. If you meant to call the 'find_by_oid_scope' method on a 'Collection' object it is failing because no such method exists.
If 'find_by_oid_scope' is a Document then you may have forgotten to register it to the connection.
 [in /Users/redy/Sites/throwcat/server/application.py:164]
2016-05-04 07:22:38,073 WARNING: Uncaught Exception: TypeError(u"'Collection' object is not callable. If you meant to call the 'find_by_oid_scope' method on a 'Collection' object it is failing because no such method exists.\nIf 'find_by_oid_scope' is a Document then you may have forgotten to register it to the connection.",)
Traceback (most recent call last):
  File "/Library/Python/2.7/site-packages/flask/app.py", line 1475, in full_dispatch_request
    rv = self.dispatch_request()
  File "/Library/Python/2.7/site-packages/flask/app.py", line 1461, in dispatch_request
    return self.view_functions[rule.endpoint](**req.view_args)
  File "/Users/redy/Sites/throwcat/server/utils/api_utils.py", line 22, in decorate
    result = f(*args, **kwargs)
  File "/Users/redy/Sites/throwcat/server/blueprints/media/controllers/base.py", line 39, in list_media
    Media.find_by_oid_scope(user['_id'], scope)
  File "/Library/Python/2.7/site-packages/mongokit/collection.py", line 75, in __call__
    "register it to the connection." % (name, name))
TypeError: 'Collection' object is not callable. If you meant to call the 'find_by_oid_scope' method on a 'Collection' object it is failing because no such method exists.
If 'find_by_oid_scope' is a Document then you may have forgotten to register it to the connection.
 [in /Users/redy/Sites/throwcat/server/application.py:164]
2016-05-04 07:23:30,350 WARNING: Uncaught Exception: TypeError(u"'Collection' object is not callable. If you meant to call the 'find_by_oid_scope' method on a 'Collection' object it is failing because no such method exists.\nIf 'find_by_oid_scope' is a Document then you may have forgotten to register it to the connection.",)
Traceback (most recent call last):
  File "/Library/Python/2.7/site-packages/flask/app.py", line 1475, in full_dispatch_request
    rv = self.dispatch_request()
  File "/Library/Python/2.7/site-packages/flask/app.py", line 1461, in dispatch_request
    return self.view_functions[rule.endpoint](**req.view_args)
  File "/Users/redy/Sites/throwcat/server/utils/api_utils.py", line 22, in decorate
    result = f(*args, **kwargs)
  File "/Users/redy/Sites/throwcat/server/blueprints/media/controllers/base.py", line 39, in list_media
    Media.find_by_oid_scope(user['_id'], scope)
  File "/Library/Python/2.7/site-packages/mongokit/collection.py", line 75, in __call__
    "register it to the connection." % (name, name))
TypeError: 'Collection' object is not callable. If you meant to call the 'find_by_oid_scope' method on a 'Collection' object it is failing because no such method exists.
If 'find_by_oid_scope' is a Document then you may have forgotten to register it to the connection.
 [in /Users/redy/Sites/throwcat/server/application.py:164]
2016-05-04 07:25:20,393 WARNING: Uncaught Exception: TypeError(u"'Collection' object is not callable. If you meant to call the 'find_by_oid_scope' method on a 'Collection' object it is failing because no such method exists.\nIf 'find_by_oid_scope' is a Document then you may have forgotten to register it to the connection.",)
Traceback (most recent call last):
  File "/Library/Python/2.7/site-packages/flask/app.py", line 1475, in full_dispatch_request
    rv = self.dispatch_request()
  File "/Library/Python/2.7/site-packages/flask/app.py", line 1461, in dispatch_request
    return self.view_functions[rule.endpoint](**req.view_args)
  File "/Users/redy/Sites/throwcat/server/utils/api_utils.py", line 22, in decorate
    result = f(*args, **kwargs)
  File "/Users/redy/Sites/throwcat/server/blueprints/media/controllers/base.py", line 35, in list_media
    Media.find_by_oid_scope(user['_id'], scope)
  File "/Library/Python/2.7/site-packages/mongokit/collection.py", line 75, in __call__
    "register it to the connection." % (name, name))
TypeError: 'Collection' object is not callable. If you meant to call the 'find_by_oid_scope' method on a 'Collection' object it is failing because no such method exists.
If 'find_by_oid_scope' is a Document then you may have forgotten to register it to the connection.
 [in /Users/redy/Sites/throwcat/server/application.py:164]
2016-05-04 07:55:57,905 WARNING: Uncaught Exception: TypeError('join() takes exactly one argument (3 given)',)
Traceback (most recent call last):
  File "/Library/Python/2.7/site-packages/flask/app.py", line 1475, in full_dispatch_request
    rv = self.dispatch_request()
  File "/Library/Python/2.7/site-packages/flask/app.py", line 1461, in dispatch_request
    return self.view_functions[rule.endpoint](**req.view_args)
  File "/Users/redy/Sites/throwcat/server/utils/api_utils.py", line 22, in decorate
    result = f(*args, **kwargs)
  File "/Users/redy/Sites/throwcat/server/blueprints/media/controllers/base.py", line 135, in save_media
    return output_media(media)
  File "/Users/redy/Sites/throwcat/server/blueprints/media/controllers/base.py", line 251, in output_media
    src = _media_src(scope, media['key'])
  File "/Users/redy/Sites/throwcat/server/blueprints/media/controllers/base.py", line 231, in _media_src
    return '/'.join(apps_static_url, scope, key)
TypeError: join() takes exactly one argument (3 given)
 [in /Users/redy/Sites/throwcat/server/application.py:162]
2016-05-04 07:56:06,177 WARNING: Uncaught Exception: TypeError('join() takes exactly one argument (3 given)',)
Traceback (most recent call last):
  File "/Library/Python/2.7/site-packages/flask/app.py", line 1475, in full_dispatch_request
    rv = self.dispatch_request()
  File "/Library/Python/2.7/site-packages/flask/app.py", line 1461, in dispatch_request
    return self.view_functions[rule.endpoint](**req.view_args)
  File "/Users/redy/Sites/throwcat/server/utils/api_utils.py", line 22, in decorate
    result = f(*args, **kwargs)
  File "/Users/redy/Sites/throwcat/server/blueprints/media/controllers/base.py", line 135, in save_media
    return output_media(media)
  File "/Users/redy/Sites/throwcat/server/blueprints/media/controllers/base.py", line 251, in output_media
    src = _media_src(scope, media['key'])
  File "/Users/redy/Sites/throwcat/server/blueprints/media/controllers/base.py", line 231, in _media_src
    return '/'.join(apps_static_url, scope, key)
TypeError: join() takes exactly one argument (3 given)
 [in /Users/redy/Sites/throwcat/server/application.py:162]
2016-05-04 07:58:35,112 WARNING: Uncaught Exception: TypeError('sequence item 0: expected string, NoneType found',)
Traceback (most recent call last):
  File "/Library/Python/2.7/site-packages/flask/app.py", line 1475, in full_dispatch_request
    rv = self.dispatch_request()
  File "/Library/Python/2.7/site-packages/flask/app.py", line 1461, in dispatch_request
    return self.view_functions[rule.endpoint](**req.view_args)
  File "/Users/redy/Sites/throwcat/server/utils/api_utils.py", line 22, in decorate
    result = f(*args, **kwargs)
  File "/Users/redy/Sites/throwcat/server/blueprints/media/controllers/base.py", line 37, in list_media
    media_list = [output_media(media) for media in medias]
  File "/Users/redy/Sites/throwcat/server/blueprints/media/controllers/base.py", line 251, in output_media
    src = _media_src(scope, media['key'])
  File "/Users/redy/Sites/throwcat/server/blueprints/media/controllers/base.py", line 231, in _media_src
    return '/'.join([apps_static_url, scope, key])
TypeError: sequence item 0: expected string, NoneType found
 [in /Users/redy/Sites/throwcat/server/application.py:162]
2016-05-04 08:04:39,719 WARNING: Uncaught Exception: TypeError('sequence item 0: expected string, NoneType found',)
Traceback (most recent call last):
  File "/Library/Python/2.7/site-packages/flask/app.py", line 1475, in full_dispatch_request
    rv = self.dispatch_request()
  File "/Library/Python/2.7/site-packages/flask/app.py", line 1461, in dispatch_request
    return self.view_functions[rule.endpoint](**req.view_args)
  File "/Users/redy/Sites/throwcat/server/utils/api_utils.py", line 22, in decorate
    result = f(*args, **kwargs)
  File "/Users/redy/Sites/throwcat/server/blueprints/media/controllers/base.py", line 37, in list_media
    media_list = [output_media(media) for media in medias]
  File "/Users/redy/Sites/throwcat/server/blueprints/media/controllers/base.py", line 251, in output_media
    src = _media_src(scope, media['key'])
  File "/Users/redy/Sites/throwcat/server/blueprints/media/controllers/base.py", line 231, in _media_src
    return '/'.join([apps_static_url, scope, key])
TypeError: sequence item 0: expected string, NoneType found
 [in /Users/redy/Sites/throwcat/server/application.py:162]
2016-05-04 08:35:43,743 WARNING: Uncaught Exception: NameError("global name 'static_url' is not defined",)
Traceback (most recent call last):
  File "/Library/Python/2.7/site-packages/flask/app.py", line 1475, in full_dispatch_request
    rv = self.dispatch_request()
  File "/Library/Python/2.7/site-packages/flask/app.py", line 1461, in dispatch_request
    return self.view_functions[rule.endpoint](**req.view_args)
  File "/Users/redy/Sites/throwcat/server/utils/api_utils.py", line 22, in decorate
    result = f(*args, **kwargs)
  File "/Users/redy/Sites/throwcat/server/blueprints/media/controllers/base.py", line 37, in list_media
    media_list = [output_media(media) for media in medias]
  File "/Users/redy/Sites/throwcat/server/blueprints/media/controllers/base.py", line 251, in output_media
    src = _media_src(scope, media['key'])
  File "/Users/redy/Sites/throwcat/server/blueprints/media/controllers/base.py", line 231, in _media_src
    return '/'.join([static_url, scope, key])
NameError: global name 'static_url' is not defined
 [in /Users/redy/Sites/throwcat/server/application.py:162]
2016-05-04 09:00:53,076 WARNING: Error: 404
Traceback (most recent call last):
  File "/Library/Python/2.7/site-packages/flask/app.py", line 1475, in full_dispatch_request
    rv = self.dispatch_request()
  File "/Library/Python/2.7/site-packages/flask/app.py", line 1453, in dispatch_request
    self.raise_routing_exception(req)
  File "/Library/Python/2.7/site-packages/flask/app.py", line 1436, in raise_routing_exception
    raise request.routing_exception
NotFound: 404: Not Found
 [in /Users/redy/Sites/throwcat/server/application.py:139]
2016-05-04 09:35:07,238 WARNING: Error: 404
Traceback (most recent call last):
  File "/Library/Python/2.7/site-packages/flask/app.py", line 1475, in full_dispatch_request
    rv = self.dispatch_request()
  File "/Library/Python/2.7/site-packages/flask/app.py", line 1453, in dispatch_request
    self.raise_routing_exception(req)
  File "/Library/Python/2.7/site-packages/flask/app.py", line 1436, in raise_routing_exception
    raise request.routing_exception
NotFound: 404: Not Found
 [in /Users/redy/Sites/throwcat/server/application.py:139]
